<?xml version="1.0"?>
<robot name="two_link_arm">

  <!-- Base link -->
  <link name="base_link">
    <visual>
      <geometry>
        <box size="0.5 0.5 0.1"/>
      </geometry>
      <material name="blue">
        <color rgba="0 0 1 1"/>
      </material>
    </visual>
  </link>

  <!-- First arm link -->
  <link name="link1">
    <visual>
      <geometry>
        <cylinder radius="0.05" length="1.0"/>
      </geometry>
      <material name="red">
        <color rgba="1 0 0 1"/>
      </material>
    </visual>
  </link>

  <!-- Second arm link -->
  <link name="link2">
    <visual>
      <geometry>
        <cylinder radius="0.05" length="0.8"/>
      </geometry>
      <material name="green">
        <color rgba="0 1 0 1"/>
      </material>
    </visual>
  </link>

  <!-- Joint 1: base_link -> link1 -->
  <joint name="joint1" type="revolute">
    <parent link="base_link"/>
    <child link="link1"/>
    <origin xyz="0 0 0.05" rpy="0 0 0"/>
    <axis xyz="0 0 1"/>
    <limit lower="-1.57" upper="1.57" effort="10" velocity="1"/>
  </joint>

  <!-- Joint 2: link1 -> link2 -->
  <joint name="joint2" type="revolute">
    <parent link="link1"/>
    <child link="link2"/>
    <origin xyz="0 0 1.0" rpy="0 0 0"/>
    <axis xyz="0 0 1"/>
    <limit lower="-1.57" upper="1.57" effort="10" velocity="1"/>
  </joint>

</robot>

